{
  "url": "https://api.github.com/repos/tensorflow/tensorflow/issues/44736",
  "repository_url": "https://api.github.com/repos/tensorflow/tensorflow",
  "labels_url": "https://api.github.com/repos/tensorflow/tensorflow/issues/44736/labels{/name}",
  "comments_url": "https://api.github.com/repos/tensorflow/tensorflow/issues/44736/comments",
  "events_url": "https://api.github.com/repos/tensorflow/tensorflow/issues/44736/events",
  "html_url": "https://github.com/tensorflow/tensorflow/issues/44736",
  "id": 740082718,
  "node_id": "MDU6SXNzdWU3NDAwODI3MTg=",
  "number": 44736,
  "title": "Validation step overwrites callback's internal predict call",
  "user": {
    "login": "creidieki",
    "id": 1367392,
    "node_id": "MDQ6VXNlcjEzNjczOTI=",
    "avatar_url": "https://avatars.githubusercontent.com/u/1367392?v=4",
    "gravatar_id": "",
    "url": "https://api.github.com/users/creidieki",
    "html_url": "https://github.com/creidieki",
    "followers_url": "https://api.github.com/users/creidieki/followers",
    "following_url": "https://api.github.com/users/creidieki/following{/other_user}",
    "gists_url": "https://api.github.com/users/creidieki/gists{/gist_id}",
    "starred_url": "https://api.github.com/users/creidieki/starred{/owner}{/repo}",
    "subscriptions_url": "https://api.github.com/users/creidieki/subscriptions",
    "organizations_url": "https://api.github.com/users/creidieki/orgs",
    "repos_url": "https://api.github.com/users/creidieki/repos",
    "events_url": "https://api.github.com/users/creidieki/events{/privacy}",
    "received_events_url": "https://api.github.com/users/creidieki/received_events",
    "type": "User",
    "site_admin": false
  },
  "labels": [
    {
      "id": 473172988,
      "node_id": "MDU6TGFiZWw0NzMxNzI5ODg=",
      "url": "https://api.github.com/repos/tensorflow/tensorflow/labels/type:bug",
      "name": "type:bug",
      "color": "159b2e",
      "default": false,
      "description": "Bug"
    },
    {
      "id": 1097546578,
      "node_id": "MDU6TGFiZWwxMDk3NTQ2NTc4",
      "url": "https://api.github.com/repos/tensorflow/tensorflow/labels/comp:keras",
      "name": "comp:keras",
      "color": "0052cc",
      "default": false,
      "description": "Keras related issues"
    },
    {
      "id": 1946362326,
      "node_id": "MDU6TGFiZWwxOTQ2MzYyMzI2",
      "url": "https://api.github.com/repos/tensorflow/tensorflow/labels/TF%202.3",
      "name": "TF 2.3",
      "color": "1d76db",
      "default": false,
      "description": "Issues related to TF 2.3"
    },
    {
      "id": 2046763290,
      "node_id": "MDU6TGFiZWwyMDQ2NzYzMjkw",
      "url": "https://api.github.com/repos/tensorflow/tensorflow/labels/Fixed%20in%20Nightly",
      "name": "Fixed in Nightly",
      "color": "5ecc37",
      "default": false,
      "description": "Issues that are resolved in nightly version"
    }
  ],
  "state": "closed",
  "locked": false,
  "assignee": {
    "login": "ravikyram",
    "id": 51902062,
    "node_id": "MDQ6VXNlcjUxOTAyMDYy",
    "avatar_url": "https://avatars.githubusercontent.com/u/51902062?v=4",
    "gravatar_id": "",
    "url": "https://api.github.com/users/ravikyram",
    "html_url": "https://github.com/ravikyram",
    "followers_url": "https://api.github.com/users/ravikyram/followers",
    "following_url": "https://api.github.com/users/ravikyram/following{/other_user}",
    "gists_url": "https://api.github.com/users/ravikyram/gists{/gist_id}",
    "starred_url": "https://api.github.com/users/ravikyram/starred{/owner}{/repo}",
    "subscriptions_url": "https://api.github.com/users/ravikyram/subscriptions",
    "organizations_url": "https://api.github.com/users/ravikyram/orgs",
    "repos_url": "https://api.github.com/users/ravikyram/repos",
    "events_url": "https://api.github.com/users/ravikyram/events{/privacy}",
    "received_events_url": "https://api.github.com/users/ravikyram/received_events",
    "type": "User",
    "site_admin": false
  },
  "assignees": [
    {
      "login": "ravikyram",
      "id": 51902062,
      "node_id": "MDQ6VXNlcjUxOTAyMDYy",
      "avatar_url": "https://avatars.githubusercontent.com/u/51902062?v=4",
      "gravatar_id": "",
      "url": "https://api.github.com/users/ravikyram",
      "html_url": "https://github.com/ravikyram",
      "followers_url": "https://api.github.com/users/ravikyram/followers",
      "following_url": "https://api.github.com/users/ravikyram/following{/other_user}",
      "gists_url": "https://api.github.com/users/ravikyram/gists{/gist_id}",
      "starred_url": "https://api.github.com/users/ravikyram/starred{/owner}{/repo}",
      "subscriptions_url": "https://api.github.com/users/ravikyram/subscriptions",
      "organizations_url": "https://api.github.com/users/ravikyram/orgs",
      "repos_url": "https://api.github.com/users/ravikyram/repos",
      "events_url": "https://api.github.com/users/ravikyram/events{/privacy}",
      "received_events_url": "https://api.github.com/users/ravikyram/received_events",
      "type": "User",
      "site_admin": false
    }
  ],
  "milestone": null,
  "comments": 3,
  "created_at": "2020-11-10T17:00:30Z",
  "updated_at": "2020-11-11T02:31:05Z",
  "closed_at": "2020-11-10T18:14:41Z",
  "author_association": "NONE",
  "active_lock_reason": null,
  "body": "**System information**\r\n- Have I written custom code (as opposed to using a stock example script provided in TensorFlow): Yes\r\n- OS Platform and Distribution (e.g., Linux Ubuntu 16.04): Ubuntu 20.04.1 LTS \r\n- Mobile device (e.g. iPhone 8, Pixel 2, Samsung Galaxy) if the issue happens on mobile device:\r\n- TensorFlow installed from (source or binary): binary\r\n- TensorFlow version (use command below): v2.3.0-54-gfcc4b966f1 2.3.1\r\n- Python version: 3.8.5\r\n- CUDA/cuDNN version: 10.1\r\n- GPU model and memory: GeForce RTX 2080 Ti 11GB x8\r\n\r\nI'm training a network, and I'm trying to collect metrics on two separate validation sets. I've been using the built-in validation for one of them, and I wrote a callback for the other. However, in epochs when both run, the callback seems to always get the same answer as the built-in validation set.\r\n\r\nI have a minimal test case below. This is a completely trivial network where the output and input are equal. I've built the situation as follows:\r\n* Let x = np.ones(5,).\r\n* It trains on input = output = x, so the training error is always 0.\r\n* It validates on input = x, output = 2*x, so the validation error is always 1.\r\n* The callback validates on input = x, output = 3*x, so the callback's validation error should always be 2.\r\n```\r\nimport numpy as np\r\nimport tensorflow as tf\r\nfrom tensorflow.keras.layers import Input\r\nfrom tensorflow.keras.models import Model\r\n\r\ninput_data = Input(shape=(5,))\r\nmodel = Model(inputs=input_data, outputs=input_data)\r\nmodel.compile(loss='mae')\r\n\r\nclass valCallback(tf.keras.callbacks.Callback):\r\n    def __init__(self, model, inputs, outputs):\r\n        self.model = model\r\n        self.inputs = inputs\r\n        self.outputs = outputs\r\n        \r\n    def on_epoch_end(self, epoch, logs={}):\r\n        val = self.model.evaluate(self.inputs, self.outputs, verbose=0)\r\n        print(\"\\nVAL: \", val)\r\n\r\ntraindata = np.ones((5))\r\nvc = valCallback(model, traindata, 3*traindata)  \r\nmodel.fit(traindata, traindata, \r\n          validation_data=(traindata, 2*traindata),\r\n          epochs=4, callbacks=[vc], validation_freq=2, verbose=0)\r\n```\r\n\r\nIn epoch 1, the callback correctly prints 2. In epoch 2, when the validation runs, the callback prints 1 instead (!).\r\n\r\nSomehow the validation_data is overwriting the data in the callback, and I don't know how or why. The self.model.evaluate calls in the callback aren't getting the right answer any more, after validation has happened.\r\n\r\nDesired output:\r\nVAL: 2\r\nVAL: 2\r\nVAL: 2\r\nVAL: 2\r\n\r\nActual output:\r\nVAL: 2\r\nVAL: 1\r\nVAL: 1\r\nVAL: 1",
  "closed_by": {
    "login": "creidieki",
    "id": 1367392,
    "node_id": "MDQ6VXNlcjEzNjczOTI=",
    "avatar_url": "https://avatars.githubusercontent.com/u/1367392?v=4",
    "gravatar_id": "",
    "url": "https://api.github.com/users/creidieki",
    "html_url": "https://github.com/creidieki",
    "followers_url": "https://api.github.com/users/creidieki/followers",
    "following_url": "https://api.github.com/users/creidieki/following{/other_user}",
    "gists_url": "https://api.github.com/users/creidieki/gists{/gist_id}",
    "starred_url": "https://api.github.com/users/creidieki/starred{/owner}{/repo}",
    "subscriptions_url": "https://api.github.com/users/creidieki/subscriptions",
    "organizations_url": "https://api.github.com/users/creidieki/orgs",
    "repos_url": "https://api.github.com/users/creidieki/repos",
    "events_url": "https://api.github.com/users/creidieki/events{/privacy}",
    "received_events_url": "https://api.github.com/users/creidieki/received_events",
    "type": "User",
    "site_admin": false
  },
  "reactions": {
    "url": "https://api.github.com/repos/tensorflow/tensorflow/issues/44736/reactions",
    "total_count": 0,
    "+1": 0,
    "-1": 0,
    "laugh": 0,
    "hooray": 0,
    "confused": 0,
    "heart": 0,
    "rocket": 0,
    "eyes": 0
  },
  "timeline_url": "https://api.github.com/repos/tensorflow/tensorflow/issues/44736/timeline",
  "performed_via_github_app": null
}
